<?xml version="1.0" encoding="UTF-8"?>
<!-- Generated by org.testng.reporters.JUnitReportReporter -->
<testsuite skipped="2" hostname="Navya-PC" name="script.ValidLogin" tests="6" failures="0" timestamp="20 Mar 2018 10:10:17 GMT" time="7.757" errors="4">
  <testcase name="closeApplication" time="0.039" classname="script.ValidLogin">
    <error type="java.lang.NullPointerException">
      <![CDATA[java.lang.NullPointerException
at generic.BaseTest.closeApplication(BaseTest.java:50)
at sun.reflect.NativeMethodAccessorImpl.invoke0(Native Method)
at sun.reflect.NativeMethodAccessorImpl.invoke(Unknown Source)
at sun.reflect.DelegatingMethodAccessorImpl.invoke(Unknown Source)
at java.lang.reflect.Method.invoke(Unknown Source)
at org.testng.internal.MethodInvocationHelper.invokeMethod(MethodInvocationHelper.java:124)
at org.testng.internal.MethodInvocationHelper.invokeMethodConsideringTimeout(MethodInvocationHelper.java:59)
at org.testng.internal.Invoker.invokeConfigurationMethod(Invoker.java:455)
at org.testng.internal.Invoker.invokeConfigurations(Invoker.java:222)
at org.testng.internal.Invoker.invokeMethod(Invoker.java:533)
at org.testng.internal.Invoker.invokeTestMethod(Invoker.java:716)
at org.testng.internal.Invoker.invokeTestMethods(Invoker.java:988)
at org.testng.internal.TestMethodWorker.invokeTestMethods(TestMethodWorker.java:125)
at org.testng.internal.TestMethodWorker.run(TestMethodWorker.java:109)
at org.testng.TestRunner.privateRun(TestRunner.java:648)
at org.testng.TestRunner.run(TestRunner.java:505)
at org.testng.SuiteRunner.runTest(SuiteRunner.java:455)
at org.testng.SuiteRunner.access$000(SuiteRunner.java:40)
at org.testng.SuiteRunner$SuiteWorker.run(SuiteRunner.java:489)
at org.testng.internal.thread.ThreadUtil$1.call(ThreadUtil.java:52)
at java.util.concurrent.FutureTask.run(Unknown Source)
at java.util.concurrent.ThreadPoolExecutor.runWorker(Unknown Source)
at java.util.concurrent.ThreadPoolExecutor$Worker.run(Unknown Source)
at java.lang.Thread.run(Unknown Source)
]]>
    </error>
  </testcase> <!-- closeApplication -->
  <testcase name="openApplication" time="3.832" classname="script.ValidLogin">
    <error type="org.openqa.selenium.remote.UnreachableBrowserException" message="Could not start a new session. Possible causes are invalid address of the remote server or browser start-up failure.
Build info: version: &#039;3.10.0&#039;, revision: &#039;176b4a9&#039;, time: &#039;2018-03-02T19:03:16.397Z&#039;
System info: host: &#039;NAVYA-PC&#039;, ip: &#039;192.168.43.220&#039;, os.name: &#039;Windows 7&#039;, os.arch: &#039;x86&#039;, os.version: &#039;6.1&#039;, java.version: &#039;1.8.0_121&#039;
Driver info: driver.version: RemoteWebDriver">
      <![CDATA[org.openqa.selenium.remote.UnreachableBrowserException: Could not start a new session. Possible causes are invalid address of the remote server or browser start-up failure.
Build info: version: '3.10.0', revision: '176b4a9', time: '2018-03-02T19:03:16.397Z'
System info: host: 'NAVYA-PC', ip: '192.168.43.220', os.name: 'Windows 7', os.arch: 'x86', os.version: '6.1', java.version: '1.8.0_121'
Driver info: driver.version: RemoteWebDriver
at org.openqa.selenium.remote.RemoteWebDriver.execute(RemoteWebDriver.java:622)
at org.openqa.selenium.remote.RemoteWebDriver.startSession(RemoteWebDriver.java:219)
at org.openqa.selenium.remote.RemoteWebDriver.<init>(RemoteWebDriver.java:142)
at org.openqa.selenium.remote.RemoteWebDriver.<init>(RemoteWebDriver.java:155)
at generic.BaseTest.openApplication(BaseTest.java:34)
at sun.reflect.NativeMethodAccessorImpl.invoke0(Native Method)
at sun.reflect.NativeMethodAccessorImpl.invoke(Unknown Source)
at sun.reflect.DelegatingMethodAccessorImpl.invoke(Unknown Source)
at java.lang.reflect.Method.invoke(Unknown Source)
at org.testng.internal.MethodInvocationHelper.invokeMethod(MethodInvocationHelper.java:124)
at org.testng.internal.MethodInvocationHelper.invokeMethodConsideringTimeout(MethodInvocationHelper.java:59)
at org.testng.internal.Invoker.invokeConfigurationMethod(Invoker.java:455)
at org.testng.internal.Invoker.invokeConfigurations(Invoker.java:222)
at org.testng.internal.Invoker.invokeMethod(Invoker.java:520)
at org.testng.internal.Invoker.invokeTestMethod(Invoker.java:716)
at org.testng.internal.Invoker.invokeTestMethods(Invoker.java:988)
at org.testng.internal.TestMethodWorker.invokeTestMethods(TestMethodWorker.java:125)
at org.testng.internal.TestMethodWorker.run(TestMethodWorker.java:109)
at org.testng.TestRunner.privateRun(TestRunner.java:648)
at org.testng.TestRunner.run(TestRunner.java:505)
at org.testng.SuiteRunner.runTest(SuiteRunner.java:455)
at org.testng.SuiteRunner.access$000(SuiteRunner.java:40)
at org.testng.SuiteRunner$SuiteWorker.run(SuiteRunner.java:489)
at org.testng.internal.thread.ThreadUtil$1.call(ThreadUtil.java:52)
at java.util.concurrent.FutureTask.run(Unknown Source)
at java.util.concurrent.ThreadPoolExecutor.runWorker(Unknown Source)
at java.util.concurrent.ThreadPoolExecutor$Worker.run(Unknown Source)
at java.lang.Thread.run(Unknown Source)
Caused by: java.net.ConnectException: Failed to connect to /192.168.43.220:4444
at okhttp3.internal.connection.RealConnection.connectSocket(RealConnection.java:240)
at okhttp3.internal.connection.RealConnection.connect(RealConnection.java:158)
at okhttp3.internal.connection.StreamAllocation.findConnection(StreamAllocation.java:256)
at okhttp3.internal.connection.StreamAllocation.findHealthyConnection(StreamAllocation.java:134)
at okhttp3.internal.connection.StreamAllocation.newStream(StreamAllocation.java:113)
at okhttp3.internal.connection.ConnectInterceptor.intercept(ConnectInterceptor.java:42)
at okhttp3.internal.http.RealInterceptorChain.proceed(RealInterceptorChain.java:147)
at okhttp3.internal.http.RealInterceptorChain.proceed(RealInterceptorChain.java:121)
at okhttp3.internal.cache.CacheInterceptor.intercept(CacheInterceptor.java:93)
at okhttp3.internal.http.RealInterceptorChain.proceed(RealInterceptorChain.java:147)
at okhttp3.internal.http.RealInterceptorChain.proceed(RealInterceptorChain.java:121)
at okhttp3.internal.http.BridgeInterceptor.intercept(BridgeInterceptor.java:93)
at okhttp3.internal.http.RealInterceptorChain.proceed(RealInterceptorChain.java:147)
at okhttp3.internal.http.RetryAndFollowUpInterceptor.intercept(RetryAndFollowUpInterceptor.java:125)
at okhttp3.internal.http.RealInterceptorChain.proceed(RealInterceptorChain.java:147)
at okhttp3.internal.http.RealInterceptorChain.proceed(RealInterceptorChain.java:121)
at okhttp3.RealCall.getResponseWithInterceptorChain(RealCall.java:200)
at okhttp3.RealCall.execute(RealCall.java:77)
at org.openqa.selenium.remote.internal.OkHttpClient.execute(OkHttpClient.java:101)
at org.openqa.selenium.remote.ProtocolHandshake.createSession(ProtocolHandshake.java:101)
at org.openqa.selenium.remote.ProtocolHandshake.createSession(ProtocolHandshake.java:73)
at org.openqa.selenium.remote.HttpCommandExecutor.execute(HttpCommandExecutor.java:138)
at org.openqa.selenium.remote.RemoteWebDriver.execute(RemoteWebDriver.java:601)
... 27 more
Caused by: java.net.ConnectException: Connection refused: connect
at java.net.DualStackPlainSocketImpl.waitForConnect(Native Method)
at java.net.DualStackPlainSocketImpl.socketConnect(Unknown Source)
at java.net.AbstractPlainSocketImpl.doConnect(Unknown Source)
at java.net.AbstractPlainSocketImpl.connectToAddress(Unknown Source)
at java.net.AbstractPlainSocketImpl.connect(Unknown Source)
at java.net.PlainSocketImpl.connect(Unknown Source)
at java.net.SocksSocketImpl.connect(Unknown Source)
at java.net.Socket.connect(Unknown Source)
at okhttp3.internal.platform.Platform.connectSocket(Platform.java:125)
at okhttp3.internal.connection.RealConnection.connectSocket(RealConnection.java:238)
... 49 more
]]>
    </error>
  </testcase> <!-- openApplication -->
  <testcase name="openApplication" time="3.851" classname="script.ValidLogin">
    <error type="org.openqa.selenium.remote.UnreachableBrowserException" message="Could not start a new session. Possible causes are invalid address of the remote server or browser start-up failure.
Build info: version: &#039;3.10.0&#039;, revision: &#039;176b4a9&#039;, time: &#039;2018-03-02T19:03:16.397Z&#039;
System info: host: &#039;NAVYA-PC&#039;, ip: &#039;192.168.43.220&#039;, os.name: &#039;Windows 7&#039;, os.arch: &#039;x86&#039;, os.version: &#039;6.1&#039;, java.version: &#039;1.8.0_121&#039;
Driver info: driver.version: RemoteWebDriver">
      <![CDATA[org.openqa.selenium.remote.UnreachableBrowserException: Could not start a new session. Possible causes are invalid address of the remote server or browser start-up failure.
Build info: version: '3.10.0', revision: '176b4a9', time: '2018-03-02T19:03:16.397Z'
System info: host: 'NAVYA-PC', ip: '192.168.43.220', os.name: 'Windows 7', os.arch: 'x86', os.version: '6.1', java.version: '1.8.0_121'
Driver info: driver.version: RemoteWebDriver
at org.openqa.selenium.remote.RemoteWebDriver.execute(RemoteWebDriver.java:622)
at org.openqa.selenium.remote.RemoteWebDriver.startSession(RemoteWebDriver.java:219)
at org.openqa.selenium.remote.RemoteWebDriver.<init>(RemoteWebDriver.java:142)
at org.openqa.selenium.remote.RemoteWebDriver.<init>(RemoteWebDriver.java:155)
at generic.BaseTest.openApplication(BaseTest.java:34)
at sun.reflect.NativeMethodAccessorImpl.invoke0(Native Method)
at sun.reflect.NativeMethodAccessorImpl.invoke(Unknown Source)
at sun.reflect.DelegatingMethodAccessorImpl.invoke(Unknown Source)
at java.lang.reflect.Method.invoke(Unknown Source)
at org.testng.internal.MethodInvocationHelper.invokeMethod(MethodInvocationHelper.java:124)
at org.testng.internal.MethodInvocationHelper.invokeMethodConsideringTimeout(MethodInvocationHelper.java:59)
at org.testng.internal.Invoker.invokeConfigurationMethod(Invoker.java:455)
at org.testng.internal.Invoker.invokeConfigurations(Invoker.java:222)
at org.testng.internal.Invoker.invokeMethod(Invoker.java:520)
at org.testng.internal.Invoker.invokeTestMethod(Invoker.java:716)
at org.testng.internal.Invoker.invokeTestMethods(Invoker.java:988)
at org.testng.internal.TestMethodWorker.invokeTestMethods(TestMethodWorker.java:125)
at org.testng.internal.TestMethodWorker.run(TestMethodWorker.java:109)
at org.testng.TestRunner.privateRun(TestRunner.java:648)
at org.testng.TestRunner.run(TestRunner.java:505)
at org.testng.SuiteRunner.runTest(SuiteRunner.java:455)
at org.testng.SuiteRunner.access$000(SuiteRunner.java:40)
at org.testng.SuiteRunner$SuiteWorker.run(SuiteRunner.java:489)
at org.testng.internal.thread.ThreadUtil$1.call(ThreadUtil.java:52)
at java.util.concurrent.FutureTask.run(Unknown Source)
at java.util.concurrent.ThreadPoolExecutor.runWorker(Unknown Source)
at java.util.concurrent.ThreadPoolExecutor$Worker.run(Unknown Source)
at java.lang.Thread.run(Unknown Source)
Caused by: java.net.ConnectException: Failed to connect to /192.168.43.220:4444
at okhttp3.internal.connection.RealConnection.connectSocket(RealConnection.java:240)
at okhttp3.internal.connection.RealConnection.connect(RealConnection.java:158)
at okhttp3.internal.connection.StreamAllocation.findConnection(StreamAllocation.java:256)
at okhttp3.internal.connection.StreamAllocation.findHealthyConnection(StreamAllocation.java:134)
at okhttp3.internal.connection.StreamAllocation.newStream(StreamAllocation.java:113)
at okhttp3.internal.connection.ConnectInterceptor.intercept(ConnectInterceptor.java:42)
at okhttp3.internal.http.RealInterceptorChain.proceed(RealInterceptorChain.java:147)
at okhttp3.internal.http.RealInterceptorChain.proceed(RealInterceptorChain.java:121)
at okhttp3.internal.cache.CacheInterceptor.intercept(CacheInterceptor.java:93)
at okhttp3.internal.http.RealInterceptorChain.proceed(RealInterceptorChain.java:147)
at okhttp3.internal.http.RealInterceptorChain.proceed(RealInterceptorChain.java:121)
at okhttp3.internal.http.BridgeInterceptor.intercept(BridgeInterceptor.java:93)
at okhttp3.internal.http.RealInterceptorChain.proceed(RealInterceptorChain.java:147)
at okhttp3.internal.http.RetryAndFollowUpInterceptor.intercept(RetryAndFollowUpInterceptor.java:125)
at okhttp3.internal.http.RealInterceptorChain.proceed(RealInterceptorChain.java:147)
at okhttp3.internal.http.RealInterceptorChain.proceed(RealInterceptorChain.java:121)
at okhttp3.RealCall.getResponseWithInterceptorChain(RealCall.java:200)
at okhttp3.RealCall.execute(RealCall.java:77)
at org.openqa.selenium.remote.internal.OkHttpClient.execute(OkHttpClient.java:101)
at org.openqa.selenium.remote.ProtocolHandshake.createSession(ProtocolHandshake.java:101)
at org.openqa.selenium.remote.ProtocolHandshake.createSession(ProtocolHandshake.java:73)
at org.openqa.selenium.remote.HttpCommandExecutor.execute(HttpCommandExecutor.java:138)
at org.openqa.selenium.remote.RemoteWebDriver.execute(RemoteWebDriver.java:601)
... 27 more
Caused by: java.net.ConnectException: Connection refused: connect
at java.net.DualStackPlainSocketImpl.waitForConnect(Native Method)
at java.net.DualStackPlainSocketImpl.socketConnect(Unknown Source)
at java.net.AbstractPlainSocketImpl.doConnect(Unknown Source)
at java.net.AbstractPlainSocketImpl.connectToAddress(Unknown Source)
at java.net.AbstractPlainSocketImpl.connect(Unknown Source)
at java.net.PlainSocketImpl.connect(Unknown Source)
at java.net.SocksSocketImpl.connect(Unknown Source)
at java.net.Socket.connect(Unknown Source)
at okhttp3.internal.platform.Platform.connectSocket(Platform.java:125)
at okhttp3.internal.connection.RealConnection.connectSocket(RealConnection.java:238)
... 49 more
]]>
    </error>
  </testcase> <!-- openApplication -->
  <testcase name="closeApplication" time="0.035" classname="script.ValidLogin">
    <error type="java.lang.NullPointerException">
      <![CDATA[java.lang.NullPointerException
at generic.BaseTest.closeApplication(BaseTest.java:50)
at sun.reflect.NativeMethodAccessorImpl.invoke0(Native Method)
at sun.reflect.NativeMethodAccessorImpl.invoke(Unknown Source)
at sun.reflect.DelegatingMethodAccessorImpl.invoke(Unknown Source)
at java.lang.reflect.Method.invoke(Unknown Source)
at org.testng.internal.MethodInvocationHelper.invokeMethod(MethodInvocationHelper.java:124)
at org.testng.internal.MethodInvocationHelper.invokeMethodConsideringTimeout(MethodInvocationHelper.java:59)
at org.testng.internal.Invoker.invokeConfigurationMethod(Invoker.java:455)
at org.testng.internal.Invoker.invokeConfigurations(Invoker.java:222)
at org.testng.internal.Invoker.invokeMethod(Invoker.java:533)
at org.testng.internal.Invoker.invokeTestMethod(Invoker.java:716)
at org.testng.internal.Invoker.invokeTestMethods(Invoker.java:988)
at org.testng.internal.TestMethodWorker.invokeTestMethods(TestMethodWorker.java:125)
at org.testng.internal.TestMethodWorker.run(TestMethodWorker.java:109)
at org.testng.TestRunner.privateRun(TestRunner.java:648)
at org.testng.TestRunner.run(TestRunner.java:505)
at org.testng.SuiteRunner.runTest(SuiteRunner.java:455)
at org.testng.SuiteRunner.access$000(SuiteRunner.java:40)
at org.testng.SuiteRunner$SuiteWorker.run(SuiteRunner.java:489)
at org.testng.internal.thread.ThreadUtil$1.call(ThreadUtil.java:52)
at java.util.concurrent.FutureTask.run(Unknown Source)
at java.util.concurrent.ThreadPoolExecutor.runWorker(Unknown Source)
at java.util.concurrent.ThreadPoolExecutor$Worker.run(Unknown Source)
at java.lang.Thread.run(Unknown Source)
]]>
    </error>
  </testcase> <!-- closeApplication -->
  <testcase name="testValidLogin" time="0.000" classname="script.ValidLogin">
    <skipped/>
  </testcase> <!-- testValidLogin -->
  <testcase name="testValidLogin" time="0.000" classname="script.ValidLogin">
    <skipped/>
  </testcase> <!-- testValidLogin -->
</testsuite> <!-- script.ValidLogin -->
